## express 错误



- 在程序执行的过程中，不可避免的会出现一些无法预料的错误，比如文件读取失败，数据库连接失败。
- 错误处理中间件是一个集中处理错误的地方。

~~~js

 app.use((err, req, res, next) => {
     res.status(500).send('服务器发生未知错误');
 })

~~~

- 当程序出现错误时，调用next()方法，并且将错误信息通过参数的形式传递给next()方法，即可触发错误处理中间件。

~~~js

 app.get("/", (req, res, next) => {
     fs.readFile("/file-does-not-exist", (err, data) => {
         if (err) {
            next(err);
         }
     });
});

~~~

## 访问不存在资源的错误

使用 `http-errors` 框架

安装: `npm install http-errors`

```js
const express = require('express');
// 导入
const createError = require('http-errors');
// express 正常资源示例
app.get('/api/user/login', (req, res, next)=>{
    res.end('login');
});
app.get('/api/user/register', (req, res, next)=>{
    res.end('register');
});


// 因为其他 api 都没有调用 next() ,所以当访问到不存在的资源时就来到如下方法,此处返回一个错误
app.use((req, res, next)=>{
    next(createError(404));
});
// 在这个方法处理错误
app.use((err, req, res, next)=>{
    console.log(err.status, err.message);
    res.end(err.message);
});

app.listen(3000, ()=>{
    console.log('listen ok');
});
```





## try catch 方式

> try catch 可以捕获异步函数以及其他同步代码在执行过程中发生的错误，但是不能其他类型的API发生的错误。

~~~js

 app.get("/", async (req, res, next) => {
     try {
         await User.find({name: '张三'})
     }catch(ex) {
         next(ex);
     }
 });

~~~

